<sdf version='1.7'>
  <world name='default'>
    <light name='sun' type='directional'>
      <cast_shadows>1</cast_shadows>
      <pose>0 0 10 0 -0 0</pose>
      <diffuse>0.8 0.8 0.8 1</diffuse>
      <specular>0.1 0.1 0.1 1</specular>
      <attenuation>
        <range>1000</range>
        <constant>0.9</constant>
        <linear>0.01</linear>
        <quadratic>0.001</quadratic>
      </attenuation>
      <direction>-0.5 0.5 -1</direction>
      <spot>
        <inner_angle>0</inner_angle>
        <outer_angle>0</outer_angle>
        <falloff>0</falloff>
      </spot>
    </light>
    <model name='ground_plane'>
      <static>1</static>
      <link name='link'>
        <collision name='collision'>
          <geometry>
            <plane>
              <normal>0 0 1</normal>
              <size>100 100</size>
            </plane>
          </geometry>
          <surface>
            <friction>
              <ode>
                <mu>100</mu>
                <mu2>50</mu2>
              </ode>
              <torsional>
                <ode/>
              </torsional>
            </friction>
            <contact>
              <ode/>
            </contact>
            <bounce/>
          </surface>
          <max_contacts>10</max_contacts>
        </collision>
        <visual name='visual'>
          <cast_shadows>0</cast_shadows>
          <geometry>
            <plane>
              <normal>0 0 1</normal>
              <size>100 100</size>
            </plane>
          </geometry>
          <material>
            <script>
              <uri>file://media/materials/scripts/gazebo.material</uri>
              <name>Gazebo/Grey</name>
            </script>
          </material>
        </visual>
        <self_collide>0</self_collide>
        <kinematic>0</kinematic>
        <gravity>1</gravity>
        <enable_wind>0</enable_wind>
      </link>
    </model>
    <gravity>0 0 -9.8</gravity>
    <magnetic_field>6e-06 2.3e-05 -4.2e-05</magnetic_field>
    <atmosphere type='adiabatic'/>
    <physics name='default_physics' default='0' type='ode'>
      <max_step_size>0.001</max_step_size>
      <real_time_factor>1</real_time_factor>
      <real_time_update_rate>1000</real_time_update_rate>
    </physics>
    <scene>
      <ambient>0.4 0.4 0.4 1</ambient>
      <background>0.7 0.7 0.7 1</background>
      <shadows>1</shadows>
    </scene>
    <spherical_coordinates>
      <surface_model>EARTH_WGS84</surface_model>
      <latitude_deg>0</latitude_deg>
      <longitude_deg>0</longitude_deg>
      <elevation>0</elevation>
      <heading_deg>0</heading_deg>
    </spherical_coordinates>
    <state world_name='default'>
      <sim_time>144 686000000</sim_time>
      <real_time>31 546676311</real_time>
      <wall_time>1762368096 922944092</wall_time>
      <iterations>31267</iterations>
      <model name='Construction Cone'>
        <pose>2.54262 4.66686 -0 0 -0 0</pose>
        <scale>1 1 1</scale>
        <link name='link'>
          <pose>2.54262 4.66686 -0 0 -0 0</pose>
          <velocity>0 0 0 0 -0 0</velocity>
          <acceleration>-0 -0 -9.79966 8.6e-05 5.8e-05 0</acceleration>
          <wrench>-0 -0 -9.79966 0 -0 0</wrench>
        </link>
      </model>
      <model name='beer'>
        <pose>3.85469 0.37343 -3e-06 1e-06 -0 0.00031</pose>
        <scale>1 1 1</scale>
        <link name='link'>
          <pose>3.85469 0.37343 0.114997 1e-06 -0 0.00031</pose>
          <velocity>1.8e-05 -8.9e-05 -0.002529 0.000776 0.00016 -4e-06</velocity>
          <acceleration>0 0 -9.8 0 -0 0</acceleration>
          <wrench>0 0 -3.822 0 -0 0</wrench>
        </link>
      </model>
      <model name='go2'>
        <pose>-0.091555 0.769466 0.1144 -0.000216 2.1e-05 0.005136</pose>
        <scale>1 1 1</scale>
        <link name='FL_calf'>
          <pose>0.30903 0.906176 0.173571 1.95439 0.371119 2.4147</pose>
          <velocity>-0.003254 0.014711 -0.124987 -0.42185 0.223111 -0.631752</velocity>
          <acceleration>0.13761 6.91045 -3.69298 -2.21276 0.506275 0.730255</acceleration>
          <wrench>0.029449 1.47883 -0.790298 0 -0 0</wrench>
        </link>
        <link name='FL_hip'>
          <pose>0.101602 0.81696 0.114386 1.04354 3e-06 0.005159</pose>
          <velocity>0.031255 -0.01815 -0.147086 -0.099499 -0.103254 0.147633</velocity>
          <acceleration>3.04683 -2.40284 -4.38631 2.29134 0.657655 3.06506</acceleration>
          <wrench>2.33692 -1.84297 -3.3643 0 -0 0</wrench>
        </link>
        <link name='FL_thigh'>
          <pose>0.101354 0.865011 0.196916 1.44465 -0.513324 -1.31292</pose>
          <velocity>0.013969 0.041755 -0.115114 -0.538967 0.33671 -0.917408</velocity>
          <acceleration>0.499447 2.16834 -0.730669 -0.191002 -1.28424 1.74199</acceleration>
          <wrench>0.619813 2.69091 -0.90676 0 -0 0</wrench>
        </link>
        <link name='FR_calf'>
          <pose>0.133679 0.858828 0.302287 -1.12051 0.275536 -0.507395</pose>
          <velocity>0.062165 -0.061083 -0.038665 0.127402 -0.262224 -0.351486</velocity>
          <acceleration>-6.93713 -3.81804 -1.2067 -2.25 1.07252 -1.81236</acceleration>
          <wrench>-1.48455 -0.817061 -0.258235 0 -0 0</wrench>
        </link>
        <link name='FR_hip'>
          <pose>0.102081 0.723961 0.114405 -1.04787 3.5e-05 0.005144</pose>
          <velocity>0.020619 -0.028456 -0.090765 -0.073101 -0.058488 0.15488</velocity>
          <acceleration>3.66767 -1.80113 -4.63389 -2.61108 0.733322 2.00329</acceleration>
          <wrench>2.8131 -1.38147 -3.55419 0 -0 0</wrench>
        </link>
        <link name='FR_thigh'>
          <pose>0.10233 0.676262 0.197141 -2.08871 -0.075821 3.01467</pose>
          <velocity>0.005379 -0.0306 -0.094794 0.025562 -0.159105 -0.100748</velocity>
          <acceleration>-2.44879 2.03203 -5.88133 -0.88077 1.48592 -2.36871</acceleration>
          <wrench>-3.03895 2.52175 -7.29873 0 -0 0</wrench>
        </link>
        <link name='RL_calf'>
          <pose>-0.07783 0.90442 0.173304 1.89738 -0.423379 -2.25546</pose>
          <velocity>-0.03786 -0.081651 -0.082265 -0.1725 -0.055379 0.396903</velocity>
          <acceleration>-4.47258 -17.1648 31.258 -2.22843 -0.750558 -2.52389</acceleration>
          <wrench>-0.957133 -3.67326 6.68921 0 -0 0</wrench>
        </link>
        <link name='RL_hip'>
          <pose>-0.285193 0.81497 0.114393 1.04207 0.000216 0.005008</pose>
          <velocity>-0.009221 0.020297 -0.1483 -0.332457 -0.056412 0.284808</velocity>
          <acceleration>5.38177 -4.53413 -10.2328 -3.10485 1.04205 0.69468</acceleration>
          <wrench>4.12782 -3.47768 -7.84854 0 -0 0</wrench>
        </link>
        <link name='RL_thigh'>
          <pose>-0.28546 0.863142 0.196846 1.44352 -0.514545 -1.31165</pose>
          <velocity>-0.026135 0.030748 -0.126233 -0.356804 0.042918 0.044278</velocity>
          <acceleration>-24.5931 12.081 24.1569 0.526189 0.896276 0.973281</acceleration>
          <wrench>-30.52 14.9925 29.9788 0 -0 0</wrench>
        </link>
        <link name='RR_calf'>
          <pose>-0.409256 0.823579 0.283692 -1.04757 -0.022091 0.044399</pose>
          <velocity>0.038189 -0.040754 -0.018406 0.392246 0.486518 0.023148</velocity>
          <acceleration>2.91879 -2.52447 -14.2429 -2.70381 1.4134 -1.25757</acceleration>
          <wrench>0.624622 -0.540236 -3.04799 0 -0 0</wrench>
        </link>
        <link name='RR_hip'>
          <pose>-0.284714 0.721972 0.114414 -1.04742 8e-06 0.005137</pose>
          <velocity>-0.020669 0.011499 -0.090797 0.386263 0.391116 0.15656</velocity>
          <acceleration>5.86597 -4.04495 -12.4543 -0.329076 -0.167217 -1.95056</acceleration>
          <wrench>4.4992 -3.10247 -9.55245 0 -0 0</wrench>
        </link>
        <link name='RR_thigh'>
          <pose>-0.284459 0.674243 0.197132 -2.00954 0.295279 -2.58118</pose>
          <velocity>0.012124 -0.017539 -0.107039 0.408957 0.391631 0.09991</velocity>
          <acceleration>3.89839 -0.432072 -13.6858 -0.505336 -1.44857 2.38811</acceleration>
          <wrench>4.83791 -0.536202 -16.9841 0 -0 0</wrench>
        </link>
        <link name='base'>
          <pose>-0.091555 0.769466 0.1144 -0.000216 2.1e-05 0.005136</pose>
          <velocity>0.010189 -0.013914 -0.104115 0.428538 0.436142 0.157113</velocity>
          <acceleration>4.28901 -3.03944 -7.57502 0.845643 1.14652 0.760495</acceleration>
          <wrench>33.6344 -23.8352 -59.4033 0 -0 0</wrench>
        </link>
      </model>
      <model name='ground_plane'>
        <pose>0 0 0 0 -0 0</pose>
        <scale>1 1 1</scale>
        <link name='link'>
          <pose>0 0 0 0 -0 0</pose>
          <velocity>0 0 0 0 -0 0</velocity>
          <acceleration>0 0 0 0 -0 0</acceleration>
          <wrench>0 0 0 0 -0 0</wrench>
        </link>
      </model>
      <model name='standpipe'>
        <pose>3.91415 2.30422 0 0 -0 0</pose>
        <scale>1 1 1</scale>
        <link name='standpipe'>
          <pose>3.91415 2.30422 0.1 0 1.57078 0</pose>
          <velocity>0 0 0 0 -0 0</velocity>
          <acceleration>0 0 0 0 -0 0</acceleration>
          <wrench>0 0 0 0 -0 0</wrench>
        </link>
      </model>
      <model name='standpipe_clone_0'>
        <pose>3.87778 2.30096 0 0 -0 0</pose>
        <scale>1 1 1</scale>
        <link name='standpipe'>
          <pose>3.87778 2.30096 0.1 0 1.57078 0</pose>
          <velocity>0 0 0 0 -0 0</velocity>
          <acceleration>0 0 0 0 -0 0</acceleration>
          <wrench>0 0 0 0 -0 0</wrench>
        </link>
      </model>
      <light name='sun'>
        <pose>0 0 10 0 -0 0</pose>
      </light>
    </state>
    <gui fullscreen='0'>
      <camera name='user_camera'>
        <pose>-3.67163 3.14479 1.41691 -0 0.272517 -0.442042</pose>
        <view_controller>orbit</view_controller>
        <projection_type>perspective</projection_type>
      </camera>
    </gui>
    <wind/>
    <model name='beer'>
      <link name='link'>
        <pose>0 0 0.115 0 -0 0</pose>
        <inertial>
          <mass>0.39</mass>
          <inertia>
            <ixx>0.00058</ixx>
            <ixy>0</ixy>
            <ixz>0</ixz>
            <iyy>0.00058</iyy>
            <iyz>0</iyz>
            <izz>0.00019</izz>
          </inertia>
          <pose>0 0 0 0 -0 0</pose>
        </inertial>
        <collision name='collision'>
          <geometry>
            <cylinder>
              <radius>0.055</radius>
              <length>0.23</length>
            </cylinder>
          </geometry>
          <max_contacts>10</max_contacts>
          <surface>
            <contact>
              <ode/>
            </contact>
            <bounce/>
            <friction>
              <torsional>
                <ode/>
              </torsional>
              <ode/>
            </friction>
          </surface>
        </collision>
        <visual name='visual'>
          <geometry>
            <cylinder>
              <radius>0.055</radius>
              <length>0.23</length>
            </cylinder>
          </geometry>
          <material>
            <script>
              <uri>model://beer/materials/scripts</uri>
              <uri>model://beer/materials/textures</uri>
              <name>Beer/Diffuse</name>
            </script>
          </material>
        </visual>
        <self_collide>0</self_collide>
        <enable_wind>0</enable_wind>
        <kinematic>0</kinematic>
      </link>
      <pose>3.8547 0.37336 0 0 -0 0</pose>
    </model>
    <model name='standpipe'>
      <static>1</static>
      <link name='standpipe'>
        <pose>0 0 0.1 0 1.57078 0</pose>
        <collision name='collision_stopper'>
          <pose>0 0 0.22 0 -0 0</pose>
          <geometry>
            <cylinder>
              <radius>0.069</radius>
              <length>0.1</length>
            </cylinder>
          </geometry>
          <surface>
            <friction>
              <ode>
                <mu>0.5</mu>
                <mu2>0.5</mu2>
              </ode>
              <torsional>
                <ode/>
              </torsional>
            </friction>
            <contact>
              <ode/>
            </contact>
            <bounce/>
          </surface>
          <max_contacts>10</max_contacts>
        </collision>
        <collision name='collision'>
          <pose>0 0 0.15 0 -0 0</pose>
          <geometry>
            <mesh>
              <uri>model://standpipe/meshes/standpipe.dae</uri>
            </mesh>
          </geometry>
          <surface>
            <friction>
              <ode>
                <mu>0.5</mu>
                <mu2>0.5</mu2>
              </ode>
              <torsional>
                <ode/>
              </torsional>
            </friction>
            <contact>
              <ode/>
            </contact>
            <bounce/>
          </surface>
          <max_contacts>10</max_contacts>
        </collision>
        <visual name='visual'>
          <pose>0 0 0.15 0 -0 0</pose>
          <geometry>
            <mesh>
              <uri>model://standpipe/meshes/standpipe.dae</uri>
            </mesh>
          </geometry>
        </visual>
        <self_collide>0</self_collide>
        <enable_wind>0</enable_wind>
        <kinematic>0</kinematic>
      </link>
      <pose>3.91415 2.30422 0 0 -0 0</pose>
    </model>
    <model name='standpipe_clone_0'>
      <static>1</static>
      <link name='standpipe'>
        <pose>0 0 0.1 0 1.57078 0</pose>
        <collision name='collision_stopper'>
          <pose>0 0 0.22 0 -0 0</pose>
          <geometry>
            <cylinder>
              <radius>0.069</radius>
              <length>0.1</length>
            </cylinder>
          </geometry>
          <surface>
            <friction>
              <ode>
                <mu>0.5</mu>
                <mu2>0.5</mu2>
              </ode>
              <torsional>
                <ode/>
              </torsional>
            </friction>
            <contact>
              <ode/>
            </contact>
            <bounce/>
          </surface>
          <max_contacts>10</max_contacts>
        </collision>
        <collision name='collision'>
          <pose>0 0 0.15 0 -0 0</pose>
          <geometry>
            <mesh>
              <uri>model://standpipe/meshes/standpipe.dae</uri>
            </mesh>
          </geometry>
          <surface>
            <friction>
              <ode>
                <mu>0.5</mu>
                <mu2>0.5</mu2>
              </ode>
              <torsional>
                <ode/>
              </torsional>
            </friction>
            <contact>
              <ode/>
            </contact>
            <bounce/>
          </surface>
          <max_contacts>10</max_contacts>
        </collision>
        <visual name='visual'>
          <pose>0 0 0.15 0 -0 0</pose>
          <geometry>
            <mesh>
              <uri>model://standpipe/meshes/standpipe.dae</uri>
            </mesh>
          </geometry>
        </visual>
        <self_collide>0</self_collide>
        <enable_wind>0</enable_wind>
        <kinematic>0</kinematic>
      </link>
      <pose>3.87778 2.30096 0 0 -0 0</pose>
    </model>
    <model name='Construction Cone'>
      <link name='link'>
        <collision name='collision'>
          <geometry>
            <mesh>
              <scale>10 10 10</scale>
              <uri>model://construction_cone/meshes/construction_cone.dae</uri>
            </mesh>
          </geometry>
          <max_contacts>10</max_contacts>
          <surface>
            <contact>
              <ode/>
            </contact>
            <bounce/>
            <friction>
              <torsional>
                <ode/>
              </torsional>
              <ode/>
            </friction>
          </surface>
        </collision>
        <visual name='visual'>
          <geometry>
            <mesh>
              <scale>10 10 10</scale>
              <uri>model://construction_cone/meshes/construction_cone.dae</uri>
            </mesh>
          </geometry>
        </visual>
        <self_collide>0</self_collide>
        <inertial>
          <pose>0 0 0 0 -0 0</pose>
          <inertia>
            <ixx>1</ixx>
            <ixy>0</ixy>
            <ixz>0</ixz>
            <iyy>1</iyy>
            <iyz>0</iyz>
            <izz>1</izz>
          </inertia>
          <mass>1</mass>
        </inertial>
        <enable_wind>0</enable_wind>
        <kinematic>0</kinematic>
      </link>
      <pose>7.95172 2.91478 0 0 -0 0</pose>
    </model>
    <audio>
      <device>default</device>
    </audio>
    <model name='go2'>
      <link name='base'>
        <inertial>
          <pose>0.040474 0.001259 0.001517 0 -0 0</pose>
          <mass>7.842</mass>
          <inertia>
            <ixx>0.0342912</ixx>
            <ixy>-0.00247632</ixy>
            <ixz>-0.0121417</ixz>
            <iyy>0.150093</iyy>
            <iyz>-0.000874341</iyz>
            <izz>0.15889</izz>
          </inertia>
        </inertial>
        <collision name='base_fixed_joint_lump__trunk_collision'>
          <pose>0 0 0 3.14159 1.57079 3.14159</pose>
          <geometry>
            <cylinder>
              <length>0.3762</length>
              <radius>0.0935</radius>
            </cylinder>
          </geometry>
          <surface>
            <contact>
              <ode>
                <kp>10000</kp>
                <kd>1</kd>
              </ode>
            </contact>
            <friction>
              <ode>
                <mu>0.2</mu>
                <mu2>0.2</mu2>
              </ode>
              <torsional>
                <ode/>
              </torsional>
            </friction>
            <bounce/>
          </surface>
          <max_contacts>10</max_contacts>
        </collision>
        <visual name='base_visual'>
          <pose>0 0 0 0 -0 0</pose>
          <geometry>
            <box>
              <size>0.001 0.001 0.001</size>
            </box>
          </geometry>
        </visual>
        <visual name='base_fixed_joint_lump__camera_link_visual_1'>
          <pose>0.317929 0 0.082538 1.8708 -0 1.5708</pose>
          <geometry>
            <box>
              <size>0.09 0.025 0.02505</size>
            </box>
          </geometry>
        </visual>
        <visual name='base_fixed_joint_lump__trunk_visual_2'>
          <pose>0 0 0 0 -0 0</pose>
          <geometry>
            <mesh>
              <scale>1 1 1</scale>
              <uri>file:///home/apampattiwar3/ros2_ws/install/go2_description/share/go2_description/meshes/trunk.dae</uri>
            </mesh>
          </geometry>
        </visual>
        <visual name='base_fixed_joint_lump__FL_hip_rotor_visual_3'>
          <pose>0.11215 0.04675 0 3.14159 1.57079 3.14159</pose>
          <geometry>
            <cylinder>
              <length>0.02</length>
              <radius>0.035</radius>
            </cylinder>
          </geometry>
        </visual>
        <visual name='base_fixed_joint_lump__FR_hip_rotor_visual_4'>
          <pose>0.11215 -0.04675 0 3.14159 1.57079 3.14159</pose>
          <geometry>
            <cylinder>
              <length>0.02</length>
              <radius>0.035</radius>
            </cylinder>
          </geometry>
        </visual>
        <visual name='base_fixed_joint_lump__RL_hip_rotor_visual_5'>
          <pose>-0.11215 0.04675 0 3.14159 1.57079 3.14159</pose>
          <geometry>
            <cylinder>
              <length>0.02</length>
              <radius>0.035</radius>
            </cylinder>
          </geometry>
        </visual>
        <visual name='base_fixed_joint_lump__RR_hip_rotor_visual_6'>
          <pose>-0.11215 -0.04675 0 3.14159 1.57079 3.14159</pose>
          <geometry>
            <cylinder>
              <length>0.02</length>
              <radius>0.035</radius>
            </cylinder>
          </geometry>
        </visual>
        <visual name='base_fixed_joint_lump__imu_link_visual_7'>
          <pose>0 0 0 0 -0 0</pose>
          <geometry>
            <box>
              <size>0.001 0.001 0.001</size>
            </box>
          </geometry>
        </visual>
        <gravity>1</gravity>
        <self_collide>0</self_collide>
        <enable_wind>0</enable_wind>
        <kinematic>0</kinematic>
        <gravity>1</gravity>
        <sensor name='cameracolor' type='camera'>
          <camera name='camera'>
            <horizontal_fov>1.0472</horizontal_fov>
            <image>
              <width>640</width>
              <height>480</height>
              <format>RGB_INT8</format>
            </image>
            <clip>
              <near>0.1</near>
              <far>100</far>
            </clip>
            <noise>
              <type>gaussian</type>
              <mean>0</mean>
              <stddev>0.007</stddev>
            </noise>
          </camera>
          <always_on>1</always_on>
          <update_rate>30</update_rate>
          <visualize>1</visualize>
          <pose>0.303694 0.0175 0.086942 0 0.3 0</pose>
        </sensor>
        <sensor name='cameraired1' type='camera'>
          <camera name='camera'>
            <horizontal_fov>1.0472</horizontal_fov>
            <image>
              <width>640</width>
              <height>480</height>
              <format>L_INT8</format>
            </image>
            <clip>
              <near>0.1</near>
              <far>100</far>
            </clip>
            <noise>
              <type>gaussian</type>
              <mean>0</mean>
              <stddev>0.05</stddev>
            </noise>
          </camera>
          <always_on>1</always_on>
          <update_rate>90</update_rate>
          <visualize>0</visualize>
          <pose>0.303694 0.0175 0.086942 0 0.3 0</pose>
        </sensor>
        <sensor name='cameraired2' type='camera'>
          <camera name='camera'>
            <horizontal_fov>1.0472</horizontal_fov>
            <image>
              <width>640</width>
              <height>480</height>
              <format>L_INT8</format>
            </image>
            <clip>
              <near>0.1</near>
              <far>100</far>
            </clip>
            <noise>
              <type>gaussian</type>
              <mean>0</mean>
              <stddev>0.05</stddev>
            </noise>
          </camera>
          <always_on>1</always_on>
          <update_rate>90</update_rate>
          <visualize>0</visualize>
          <pose>0.303694 0.0175 0.086942 0 0.3 0</pose>
        </sensor>
        <sensor name='cameradepth' type='depth'>
          <camera name='camera'>
            <horizontal_fov>1.48702</horizontal_fov>
            <image>
              <width>640</width>
              <height>480</height>
            </image>
            <clip>
              <near>0.1</near>
              <far>100</far>
            </clip>
            <noise>
              <type>gaussian</type>
              <mean>0</mean>
              <stddev>0.1</stddev>
            </noise>
          </camera>
          <always_on>1</always_on>
          <update_rate>60</update_rate>
          <visualize>0</visualize>
          <pose>0.303694 0.0175 0.086942 0 0.3 0</pose>
        </sensor>
        <sensor name='imu_sensor' type='imu'>
          <always_on>1</always_on>
          <update_rate>100</update_rate>
          <imu>
            <angular_velocity>
              <x>
                <noise type='gaussian'>
                  <mean>0</mean>
                  <stddev>0.0002</stddev>
                </noise>
              </x>
              <y>
                <noise type='gaussian'>
                  <mean>0</mean>
                  <stddev>0.0002</stddev>
                </noise>
              </y>
              <z>
                <noise type='gaussian'>
                  <mean>0</mean>
                  <stddev>0.0002</stddev>
                </noise>
              </z>
            </angular_velocity>
            <linear_acceleration>
              <x>
                <noise type='gaussian'>
                  <mean>0</mean>
                  <stddev>0.017</stddev>
                </noise>
              </x>
              <y>
                <noise type='gaussian'>
                  <mean>0</mean>
                  <stddev>0.017</stddev>
                </noise>
              </y>
              <z>
                <noise type='gaussian'>
                  <mean>0</mean>
                  <stddev>0.017</stddev>
                </noise>
              </z>
            </linear_acceleration>
          </imu>
          <plugin name='imu_plugin' filename='libgazebo_ros_imu_sensor.so'>
            <ros>
              <remapping>~/out:=/trunk_imu</remapping>
            </ros>
            <initial_orientation_as_reference>0</initial_orientation_as_reference>
          </plugin>
          <pose>0 0 0 0 -0 0</pose>
        </sensor>
      </link>
      <joint name='FL_hip_joint' type='revolute'>
        <pose relative_to='base'>0.1934 0.0465 0 0 -0 0</pose>
        <parent>base</parent>
        <child>FL_hip</child>
        <axis>
          <xyz>1 0 0</xyz>
          <limit>
            <lower>-1.0472</lower>
            <upper>1.0472</upper>
            <effort>23.7</effort>
            <velocity>30.1</velocity>
          </limit>
          <dynamics>
            <damping>0</damping>
            <friction>0</friction>
            <spring_reference>0</spring_reference>
            <spring_stiffness>0</spring_stiffness>
          </dynamics>
        </axis>
      </joint>
      <link name='FL_hip'>
        <pose relative_to='FL_hip_joint'>0 0 0 0 -0 0</pose>
        <inertial>
          <pose>-0.004773 0.001697 -9.3e-05 0 -0 0</pose>
          <mass>0.767</mass>
          <inertia>
            <ixx>0.000539992</ixx>
            <ixy>-2.1221e-06</ixy>
            <ixz>1.06539e-06</ixz>
            <iyy>0.000998137</iyy>
            <iyz>-1.40274e-06</iyz>
            <izz>0.000658285</izz>
          </inertia>
        </inertial>
        <collision name='FL_hip_collision'>
          <pose>0 0.0955 0 1.5708 -0 0</pose>
          <geometry>
            <cylinder>
              <length>0.04</length>
              <radius>0.046</radius>
            </cylinder>
          </geometry>
          <surface>
            <contact>
              <ode/>
            </contact>
            <friction>
              <ode>
                <mu>0.2</mu>
                <mu2>0.2</mu2>
              </ode>
              <torsional>
                <ode/>
              </torsional>
            </friction>
            <bounce/>
          </surface>
          <max_contacts>10</max_contacts>
        </collision>
        <visual name='FL_hip_visual'>
          <pose>0 0 0 0 -0 0</pose>
          <geometry>
            <mesh>
              <scale>1 1 1</scale>
              <uri>file:///home/apampattiwar3/ros2_ws/install/go2_description/share/go2_description/meshes/hip.dae</uri>
            </mesh>
          </geometry>
        </visual>
        <visual name='FL_hip_fixed_joint_lump__FL_thigh_rotor_visual_1'>
          <pose>0 -0.00015 0 1.5708 -0 0</pose>
          <geometry>
            <cylinder>
              <length>0.02</length>
              <radius>0.035</radius>
            </cylinder>
          </geometry>
        </visual>
        <self_collide>0</self_collide>
        <enable_wind>0</enable_wind>
        <kinematic>0</kinematic>
      </link>
      <joint name='FL_thigh_joint' type='revolute'>
        <pose relative_to='FL_hip'>0 0.0955 0 0 -0 0</pose>
        <parent>FL_hip</parent>
        <child>FL_thigh</child>
        <axis>
          <xyz>0 1 0</xyz>
          <limit>
            <lower>-1.5708</lower>
            <upper>3.4907</upper>
            <effort>23.7</effort>
            <velocity>30.1</velocity>
          </limit>
          <dynamics>
            <damping>0</damping>
            <friction>0</friction>
            <spring_reference>0</spring_reference>
            <spring_stiffness>0</spring_stiffness>
          </dynamics>
        </axis>
      </joint>
      <link name='FL_thigh'>
        <pose relative_to='FL_thigh_joint'>0 0 0 0 -0 0</pose>
        <inertial>
          <pose>-0.003472 -0.023021 -0.030355 0 -0 0</pose>
          <mass>1.241</mass>
          <inertia>
            <ixx>0.00599633</ixx>
            <ixy>9.03053e-05</ixy>
            <ixz>-0.000299104</ixz>
            <iyy>0.00600134</iyy>
            <iyz>0.000835151</iyz>
            <izz>0.00109915</izz>
          </inertia>
        </inertial>
        <collision name='FL_thigh_collision'>
          <pose>0 0 -0.1065 0 -0 0</pose>
          <geometry>
            <cylinder>
              <length>0.213</length>
              <radius>0.017</radius>
            </cylinder>
          </geometry>
          <surface>
            <contact>
              <ode>
                <kp>1e+06</kp>
                <kd>1</kd>
              </ode>
            </contact>
            <friction>
              <ode>
                <mu>0.2</mu>
                <mu2>0.2</mu2>
              </ode>
              <torsional>
                <ode/>
              </torsional>
            </friction>
            <bounce/>
          </surface>
          <max_contacts>10</max_contacts>
        </collision>
        <visual name='FL_thigh_visual'>
          <pose>0 0 0 0 -0 0</pose>
          <geometry>
            <mesh>
              <scale>1 1 1</scale>
              <uri>file:///home/apampattiwar3/ros2_ws/install/go2_description/share/go2_description/meshes/thigh.dae</uri>
            </mesh>
          </geometry>
        </visual>
        <visual name='FL_thigh_fixed_joint_lump__FL_calf_rotor_visual_1'>
          <pose>0 -0.03235 0 1.5708 -0 0</pose>
          <geometry>
            <cylinder>
              <length>0.02</length>
              <radius>0.035</radius>
            </cylinder>
          </geometry>
        </visual>
        <self_collide>1</self_collide>
        <enable_wind>0</enable_wind>
        <kinematic>0</kinematic>
      </link>
      <joint name='FL_calf_joint' type='revolute'>
        <pose relative_to='FL_thigh'>0 0 -0.213 0 -0 0</pose>
        <parent>FL_thigh</parent>
        <child>FL_calf</child>
        <axis>
          <xyz>0 1 0</xyz>
          <limit>
            <lower>-2.7227</lower>
            <upper>-0.83776</upper>
            <effort>35.55</effort>
            <velocity>20.06</velocity>
          </limit>
          <dynamics>
            <damping>0</damping>
            <friction>0</friction>
            <spring_reference>0</spring_reference>
            <spring_stiffness>0</spring_stiffness>
          </dynamics>
        </axis>
      </joint>
      <link name='FL_calf'>
        <pose relative_to='FL_calf_joint'>0 0 0 0 -0 0</pose>
        <inertial>
          <pose>0.003944 -0.000702 -0.142477 0 -0 0</pose>
          <mass>0.214</mass>
          <inertia>
            <ixx>0.00150432</ixx>
            <ixy>5.70698e-07</ixy>
            <ixz>-5.98808e-06</ixz>
            <iyy>0.00152557</iyy>
            <iyz>1.24056e-05</iyz>
            <izz>4.38377e-05</izz>
          </inertia>
        </inertial>
        <collision name='FL_calf_collision'>
          <pose>0 0 -0.1065 0 -0 0</pose>
          <geometry>
            <cylinder>
              <length>0.213</length>
              <radius>0.008</radius>
            </cylinder>
          </geometry>
          <surface>
            <contact>
              <ode/>
            </contact>
            <friction>
              <ode>
                <mu>0.2</mu>
                <mu2>0.2</mu2>
              </ode>
              <torsional>
                <ode/>
              </torsional>
            </friction>
            <bounce/>
          </surface>
          <max_contacts>10</max_contacts>
        </collision>
        <collision name='FL_calf_fixed_joint_lump__FL_foot_collision_1'>
          <pose>0 0 -0.213 0 -0 0</pose>
          <geometry>
            <sphere>
              <radius>0.02</radius>
            </sphere>
          </geometry>
          <surface>
            <contact>
              <ode>
                <kp>1e+06</kp>
                <kd>1</kd>
              </ode>
            </contact>
            <friction>
              <ode>
                <mu>0.6</mu>
                <mu2>0.6</mu2>
              </ode>
              <torsional>
                <ode/>
              </torsional>
            </friction>
            <bounce/>
          </surface>
          <max_contacts>10</max_contacts>
        </collision>
        <visual name='FL_calf_visual'>
          <pose>0 0 0 0 -0 0</pose>
          <geometry>
            <mesh>
              <scale>1 1 1</scale>
              <uri>file:///home/apampattiwar3/ros2_ws/install/go2_description/share/go2_description/meshes/calf.dae</uri>
            </mesh>
          </geometry>
        </visual>
        <visual name='FL_calf_fixed_joint_lump__FL_foot_visual_1'>
          <pose>0 0 -0.213 0 -0 0</pose>
          <geometry>
            <sphere>
              <radius>0.01</radius>
            </sphere>
          </geometry>
        </visual>
        <self_collide>1</self_collide>
        <self_collide>1</self_collide>
        <enable_wind>0</enable_wind>
        <kinematic>0</kinematic>
      </link>
      <joint name='FR_hip_joint' type='revolute'>
        <pose relative_to='base'>0.1934 -0.0465 0 0 -0 0</pose>
        <parent>base</parent>
        <child>FR_hip</child>
        <axis>
          <xyz>1 0 0</xyz>
          <limit>
            <lower>-1.0472</lower>
            <upper>1.0472</upper>
            <effort>23.7</effort>
            <velocity>30.1</velocity>
          </limit>
          <dynamics>
            <damping>0</damping>
            <friction>0</friction>
            <spring_reference>0</spring_reference>
            <spring_stiffness>0</spring_stiffness>
          </dynamics>
        </axis>
      </joint>
      <link name='FR_hip'>
        <pose relative_to='FR_hip_joint'>0 0 0 0 -0 0</pose>
        <inertial>
          <pose>-0.004773 -0.001697 -9.3e-05 0 -0 0</pose>
          <mass>0.767</mass>
          <inertia>
            <ixx>0.000539992</ixx>
            <ixy>2.1221e-06</ixy>
            <ixz>1.06539e-06</ixz>
            <iyy>0.000998137</iyy>
            <iyz>1.40274e-06</iyz>
            <izz>0.000658285</izz>
          </inertia>
        </inertial>
        <collision name='FR_hip_collision'>
          <pose>0 -0.0955 0 1.5708 -0 0</pose>
          <geometry>
            <cylinder>
              <length>0.04</length>
              <radius>0.046</radius>
            </cylinder>
          </geometry>
          <surface>
            <contact>
              <ode/>
            </contact>
            <friction>
              <ode>
                <mu>0.2</mu>
                <mu2>0.2</mu2>
              </ode>
              <torsional>
                <ode/>
              </torsional>
            </friction>
            <bounce/>
          </surface>
          <max_contacts>10</max_contacts>
        </collision>
        <visual name='FR_hip_visual'>
          <pose>0 0 0 3.14159 -0 0</pose>
          <geometry>
            <mesh>
              <scale>1 1 1</scale>
              <uri>file:///home/apampattiwar3/ros2_ws/install/go2_description/share/go2_description/meshes/hip.dae</uri>
            </mesh>
          </geometry>
        </visual>
        <visual name='FR_hip_fixed_joint_lump__FR_thigh_rotor_visual_1'>
          <pose>0 0.00015 0 1.5708 -0 0</pose>
          <geometry>
            <cylinder>
              <length>0.02</length>
              <radius>0.035</radius>
            </cylinder>
          </geometry>
        </visual>
        <self_collide>0</self_collide>
        <enable_wind>0</enable_wind>
        <kinematic>0</kinematic>
      </link>
      <joint name='FR_thigh_joint' type='revolute'>
        <pose relative_to='FR_hip'>0 -0.0955 0 0 -0 0</pose>
        <parent>FR_hip</parent>
        <child>FR_thigh</child>
        <axis>
          <xyz>0 1 0</xyz>
          <limit>
            <lower>-1.5708</lower>
            <upper>3.4907</upper>
            <effort>23.7</effort>
            <velocity>30.1</velocity>
          </limit>
          <dynamics>
            <damping>0</damping>
            <friction>0</friction>
            <spring_reference>0</spring_reference>
            <spring_stiffness>0</spring_stiffness>
          </dynamics>
        </axis>
      </joint>
      <link name='FR_thigh'>
        <pose relative_to='FR_thigh_joint'>0 0 0 0 -0 0</pose>
        <inertial>
          <pose>-0.003472 0.023021 -0.030355 0 -0 0</pose>
          <mass>1.241</mass>
          <inertia>
            <ixx>0.00599633</ixx>
            <ixy>-9.03053e-05</ixy>
            <ixz>-0.000299104</ixz>
            <iyy>0.00600134</iyy>
            <iyz>-0.000835151</iyz>
            <izz>0.00109915</izz>
          </inertia>
        </inertial>
        <collision name='FR_thigh_collision'>
          <pose>0 0 -0.1065 0 -0 0</pose>
          <geometry>
            <cylinder>
              <length>0.213</length>
              <radius>0.017</radius>
            </cylinder>
          </geometry>
          <surface>
            <contact>
              <ode>
                <kp>1e+06</kp>
                <kd>1</kd>
              </ode>
            </contact>
            <friction>
              <ode>
                <mu>0.2</mu>
                <mu2>0.2</mu2>
              </ode>
              <torsional>
                <ode/>
              </torsional>
            </friction>
            <bounce/>
          </surface>
          <max_contacts>10</max_contacts>
        </collision>
        <visual name='FR_thigh_visual'>
          <pose>0 0 0 0 -0 0</pose>
          <geometry>
            <mesh>
              <scale>1 1 1</scale>
              <uri>file:///home/apampattiwar3/ros2_ws/install/go2_description/share/go2_description/meshes/thigh_mirror.dae</uri>
            </mesh>
          </geometry>
        </visual>
        <visual name='FR_thigh_fixed_joint_lump__FR_calf_rotor_visual_1'>
          <pose>0 0.03235 0 1.5708 -0 0</pose>
          <geometry>
            <cylinder>
              <length>0.02</length>
              <radius>0.035</radius>
            </cylinder>
          </geometry>
        </visual>
        <self_collide>1</self_collide>
        <enable_wind>0</enable_wind>
        <kinematic>0</kinematic>
      </link>
      <joint name='FR_calf_joint' type='revolute'>
        <pose relative_to='FR_thigh'>0 0 -0.213 0 -0 0</pose>
        <parent>FR_thigh</parent>
        <child>FR_calf</child>
        <axis>
          <xyz>0 1 0</xyz>
          <limit>
            <lower>-2.7227</lower>
            <upper>-0.83776</upper>
            <effort>35.55</effort>
            <velocity>20.06</velocity>
          </limit>
          <dynamics>
            <damping>0</damping>
            <friction>0</friction>
            <spring_reference>0</spring_reference>
            <spring_stiffness>0</spring_stiffness>
          </dynamics>
        </axis>
      </joint>
      <link name='FR_calf'>
        <pose relative_to='FR_calf_joint'>0 0 0 0 -0 0</pose>
        <inertial>
          <pose>0.003944 -0.000702 -0.142477 0 -0 0</pose>
          <mass>0.214</mass>
          <inertia>
            <ixx>0.00150432</ixx>
            <ixy>5.70698e-07</ixy>
            <ixz>-5.98808e-06</ixz>
            <iyy>0.00152557</iyy>
            <iyz>1.24056e-05</iyz>
            <izz>4.38377e-05</izz>
          </inertia>
        </inertial>
        <collision name='FR_calf_collision'>
          <pose>0 0 -0.1065 0 -0 0</pose>
          <geometry>
            <cylinder>
              <length>0.213</length>
              <radius>0.008</radius>
            </cylinder>
          </geometry>
          <surface>
            <contact>
              <ode/>
            </contact>
            <friction>
              <ode>
                <mu>0.2</mu>
                <mu2>0.2</mu2>
              </ode>
              <torsional>
                <ode/>
              </torsional>
            </friction>
            <bounce/>
          </surface>
          <max_contacts>10</max_contacts>
        </collision>
        <collision name='FR_calf_fixed_joint_lump__FR_foot_collision_1'>
          <pose>0 0 -0.213 0 -0 0</pose>
          <geometry>
            <sphere>
              <radius>0.02</radius>
            </sphere>
          </geometry>
          <surface>
            <contact>
              <ode>
                <kp>1e+06</kp>
                <kd>1</kd>
              </ode>
            </contact>
            <friction>
              <ode>
                <mu>0.6</mu>
                <mu2>0.6</mu2>
              </ode>
              <torsional>
                <ode/>
              </torsional>
            </friction>
            <bounce/>
          </surface>
          <max_contacts>10</max_contacts>
        </collision>
        <visual name='FR_calf_visual'>
          <pose>0 0 0 0 -0 0</pose>
          <geometry>
            <mesh>
              <scale>1 1 1</scale>
              <uri>file:///home/apampattiwar3/ros2_ws/install/go2_description/share/go2_description/meshes/calf.dae</uri>
            </mesh>
          </geometry>
        </visual>
        <visual name='FR_calf_fixed_joint_lump__FR_foot_visual_1'>
          <pose>0 0 -0.213 0 -0 0</pose>
          <geometry>
            <sphere>
              <radius>0.01</radius>
            </sphere>
          </geometry>
        </visual>
        <self_collide>1</self_collide>
        <self_collide>1</self_collide>
        <enable_wind>0</enable_wind>
        <kinematic>0</kinematic>
      </link>
      <joint name='RL_hip_joint' type='revolute'>
        <pose relative_to='base'>-0.1934 0.0465 0 0 -0 0</pose>
        <parent>base</parent>
        <child>RL_hip</child>
        <axis>
          <xyz>1 0 0</xyz>
          <limit>
            <lower>-1.0472</lower>
            <upper>1.0472</upper>
            <effort>23.7</effort>
            <velocity>30.1</velocity>
          </limit>
          <dynamics>
            <damping>0</damping>
            <friction>0</friction>
            <spring_reference>0</spring_reference>
            <spring_stiffness>0</spring_stiffness>
          </dynamics>
        </axis>
      </joint>
      <link name='RL_hip'>
        <pose relative_to='RL_hip_joint'>0 0 0 0 -0 0</pose>
        <inertial>
          <pose>0.004773 0.001697 -9.3e-05 0 -0 0</pose>
          <mass>0.767</mass>
          <inertia>
            <ixx>0.000539992</ixx>
            <ixy>2.1221e-06</ixy>
            <ixz>-1.06539e-06</ixz>
            <iyy>0.000998137</iyy>
            <iyz>-1.40274e-06</iyz>
            <izz>0.000658285</izz>
          </inertia>
        </inertial>
        <collision name='RL_hip_collision'>
          <pose>0 0.0955 0 1.5708 -0 0</pose>
          <geometry>
            <cylinder>
              <length>0.04</length>
              <radius>0.046</radius>
            </cylinder>
          </geometry>
          <surface>
            <contact>
              <ode/>
            </contact>
            <friction>
              <ode>
                <mu>0.2</mu>
                <mu2>0.2</mu2>
              </ode>
              <torsional>
                <ode/>
              </torsional>
            </friction>
            <bounce/>
          </surface>
          <max_contacts>10</max_contacts>
        </collision>
        <visual name='RL_hip_visual'>
          <pose>0 0 0 3.14159 -0 3.14159</pose>
          <geometry>
            <mesh>
              <scale>1 1 1</scale>
              <uri>file:///home/apampattiwar3/ros2_ws/install/go2_description/share/go2_description/meshes/hip.dae</uri>
            </mesh>
          </geometry>
        </visual>
        <visual name='RL_hip_fixed_joint_lump__RL_thigh_rotor_visual_1'>
          <pose>0 -0.00015 0 1.5708 -0 0</pose>
          <geometry>
            <cylinder>
              <length>0.02</length>
              <radius>0.035</radius>
            </cylinder>
          </geometry>
        </visual>
        <self_collide>0</self_collide>
        <enable_wind>0</enable_wind>
        <kinematic>0</kinematic>
      </link>
      <joint name='RL_thigh_joint' type='revolute'>
        <pose relative_to='RL_hip'>0 0.0955 0 0 -0 0</pose>
        <parent>RL_hip</parent>
        <child>RL_thigh</child>
        <axis>
          <xyz>0 1 0</xyz>
          <limit>
            <lower>-1.5708</lower>
            <upper>3.4907</upper>
            <effort>23.7</effort>
            <velocity>30.1</velocity>
          </limit>
          <dynamics>
            <damping>0</damping>
            <friction>0</friction>
            <spring_reference>0</spring_reference>
            <spring_stiffness>0</spring_stiffness>
          </dynamics>
        </axis>
      </joint>
      <link name='RL_thigh'>
        <pose relative_to='RL_thigh_joint'>0 0 0 0 -0 0</pose>
        <inertial>
          <pose>-0.003472 -0.023021 -0.030355 0 -0 0</pose>
          <mass>1.241</mass>
          <inertia>
            <ixx>0.00599633</ixx>
            <ixy>9.03053e-05</ixy>
            <ixz>-0.000299104</ixz>
            <iyy>0.00600134</iyy>
            <iyz>0.000835151</iyz>
            <izz>0.00109915</izz>
          </inertia>
        </inertial>
        <collision name='RL_thigh_collision'>
          <pose>0 0 -0.1065 0 -0 0</pose>
          <geometry>
            <cylinder>
              <length>0.213</length>
              <radius>0.017</radius>
            </cylinder>
          </geometry>
          <surface>
            <contact>
              <ode>
                <kp>1e+06</kp>
                <kd>1</kd>
              </ode>
            </contact>
            <friction>
              <ode>
                <mu>0.2</mu>
                <mu2>0.2</mu2>
              </ode>
              <torsional>
                <ode/>
              </torsional>
            </friction>
            <bounce/>
          </surface>
          <max_contacts>10</max_contacts>
        </collision>
        <visual name='RL_thigh_visual'>
          <pose>0 0 0 0 -0 0</pose>
          <geometry>
            <mesh>
              <scale>1 1 1</scale>
              <uri>file:///home/apampattiwar3/ros2_ws/install/go2_description/share/go2_description/meshes/thigh.dae</uri>
            </mesh>
          </geometry>
        </visual>
        <visual name='RL_thigh_fixed_joint_lump__RL_calf_rotor_visual_1'>
          <pose>0 -0.03235 0 1.5708 -0 0</pose>
          <geometry>
            <cylinder>
              <length>0.02</length>
              <radius>0.035</radius>
            </cylinder>
          </geometry>
        </visual>
        <self_collide>1</self_collide>
        <enable_wind>0</enable_wind>
        <kinematic>0</kinematic>
      </link>
      <joint name='RL_calf_joint' type='revolute'>
        <pose relative_to='RL_thigh'>0 0 -0.213 0 -0 0</pose>
        <parent>RL_thigh</parent>
        <child>RL_calf</child>
        <axis>
          <xyz>0 1 0</xyz>
          <limit>
            <lower>-2.7227</lower>
            <upper>-0.83776</upper>
            <effort>35.55</effort>
            <velocity>20.06</velocity>
          </limit>
          <dynamics>
            <damping>0</damping>
            <friction>0</friction>
            <spring_reference>0</spring_reference>
            <spring_stiffness>0</spring_stiffness>
          </dynamics>
        </axis>
      </joint>
      <link name='RL_calf'>
        <pose relative_to='RL_calf_joint'>0 0 0 0 -0 0</pose>
        <inertial>
          <pose>0.003944 -0.000702 -0.142477 0 -0 0</pose>
          <mass>0.214</mass>
          <inertia>
            <ixx>0.00150432</ixx>
            <ixy>5.70698e-07</ixy>
            <ixz>-5.98808e-06</ixz>
            <iyy>0.00152557</iyy>
            <iyz>1.24056e-05</iyz>
            <izz>4.38377e-05</izz>
          </inertia>
        </inertial>
        <collision name='RL_calf_collision'>
          <pose>0 0 -0.1065 0 -0 0</pose>
          <geometry>
            <cylinder>
              <length>0.213</length>
              <radius>0.008</radius>
            </cylinder>
          </geometry>
          <surface>
            <contact>
              <ode/>
            </contact>
            <friction>
              <ode>
                <mu>0.2</mu>
                <mu2>0.2</mu2>
              </ode>
              <torsional>
                <ode/>
              </torsional>
            </friction>
            <bounce/>
          </surface>
          <max_contacts>10</max_contacts>
        </collision>
        <collision name='RL_calf_fixed_joint_lump__RL_foot_collision_1'>
          <pose>0 0 -0.213 0 -0 0</pose>
          <geometry>
            <sphere>
              <radius>0.02</radius>
            </sphere>
          </geometry>
          <surface>
            <contact>
              <ode>
                <kp>1e+06</kp>
                <kd>1</kd>
              </ode>
            </contact>
            <friction>
              <ode>
                <mu>0.6</mu>
                <mu2>0.6</mu2>
              </ode>
              <torsional>
                <ode/>
              </torsional>
            </friction>
            <bounce/>
          </surface>
          <max_contacts>10</max_contacts>
        </collision>
        <visual name='RL_calf_visual'>
          <pose>0 0 0 0 -0 0</pose>
          <geometry>
            <mesh>
              <scale>1 1 1</scale>
              <uri>file:///home/apampattiwar3/ros2_ws/install/go2_description/share/go2_description/meshes/calf.dae</uri>
            </mesh>
          </geometry>
        </visual>
        <visual name='RL_calf_fixed_joint_lump__RL_foot_visual_1'>
          <pose>0 0 -0.213 0 -0 0</pose>
          <geometry>
            <sphere>
              <radius>0.01</radius>
            </sphere>
          </geometry>
        </visual>
        <self_collide>1</self_collide>
        <self_collide>1</self_collide>
        <enable_wind>0</enable_wind>
        <kinematic>0</kinematic>
      </link>
      <joint name='RR_hip_joint' type='revolute'>
        <pose relative_to='base'>-0.1934 -0.0465 0 0 -0 0</pose>
        <parent>base</parent>
        <child>RR_hip</child>
        <axis>
          <xyz>1 0 0</xyz>
          <limit>
            <lower>-1.0472</lower>
            <upper>1.0472</upper>
            <effort>23.7</effort>
            <velocity>30.1</velocity>
          </limit>
          <dynamics>
            <damping>0</damping>
            <friction>0</friction>
            <spring_reference>0</spring_reference>
            <spring_stiffness>0</spring_stiffness>
          </dynamics>
        </axis>
      </joint>
      <link name='RR_hip'>
        <pose relative_to='RR_hip_joint'>0 0 0 0 -0 0</pose>
        <inertial>
          <pose>0.004773 -0.001697 -9.3e-05 0 -0 0</pose>
          <mass>0.767</mass>
          <inertia>
            <ixx>0.000539992</ixx>
            <ixy>-2.1221e-06</ixy>
            <ixz>-1.06539e-06</ixz>
            <iyy>0.000998137</iyy>
            <iyz>1.40274e-06</iyz>
            <izz>0.000658285</izz>
          </inertia>
        </inertial>
        <collision name='RR_hip_collision'>
          <pose>0 -0.0955 0 1.5708 -0 0</pose>
          <geometry>
            <cylinder>
              <length>0.04</length>
              <radius>0.046</radius>
            </cylinder>
          </geometry>
          <surface>
            <contact>
              <ode/>
            </contact>
            <friction>
              <ode>
                <mu>0.2</mu>
                <mu2>0.2</mu2>
              </ode>
              <torsional>
                <ode/>
              </torsional>
            </friction>
            <bounce/>
          </surface>
          <max_contacts>10</max_contacts>
        </collision>
        <visual name='RR_hip_visual'>
          <pose>0 0 0 0 -0 3.14159</pose>
          <geometry>
            <mesh>
              <scale>1 1 1</scale>
              <uri>file:///home/apampattiwar3/ros2_ws/install/go2_description/share/go2_description/meshes/hip.dae</uri>
            </mesh>
          </geometry>
        </visual>
        <visual name='RR_hip_fixed_joint_lump__RR_thigh_rotor_visual_1'>
          <pose>0 0.00015 0 1.5708 -0 0</pose>
          <geometry>
            <cylinder>
              <length>0.02</length>
              <radius>0.035</radius>
            </cylinder>
          </geometry>
        </visual>
        <self_collide>0</self_collide>
        <enable_wind>0</enable_wind>
        <kinematic>0</kinematic>
      </link>
      <joint name='RR_thigh_joint' type='revolute'>
        <pose relative_to='RR_hip'>0 -0.0955 0 0 -0 0</pose>
        <parent>RR_hip</parent>
        <child>RR_thigh</child>
        <axis>
          <xyz>0 1 0</xyz>
          <limit>
            <lower>-1.5708</lower>
            <upper>3.4907</upper>
            <effort>23.7</effort>
            <velocity>30.1</velocity>
          </limit>
          <dynamics>
            <damping>0</damping>
            <friction>0</friction>
            <spring_reference>0</spring_reference>
            <spring_stiffness>0</spring_stiffness>
          </dynamics>
        </axis>
      </joint>
      <link name='RR_thigh'>
        <pose relative_to='RR_thigh_joint'>0 0 0 0 -0 0</pose>
        <inertial>
          <pose>-0.003472 0.023021 -0.030355 0 -0 0</pose>
          <mass>1.241</mass>
          <inertia>
            <ixx>0.00599633</ixx>
            <ixy>-9.03053e-05</ixy>
            <ixz>-0.000299104</ixz>
            <iyy>0.00600134</iyy>
            <iyz>-0.000835151</iyz>
            <izz>0.00109915</izz>
          </inertia>
        </inertial>
        <collision name='RR_thigh_collision'>
          <pose>0 0 -0.1065 0 -0 0</pose>
          <geometry>
            <cylinder>
              <length>0.213</length>
              <radius>0.017</radius>
            </cylinder>
          </geometry>
          <surface>
            <contact>
              <ode>
                <kp>1e+06</kp>
                <kd>1</kd>
              </ode>
            </contact>
            <friction>
              <ode>
                <mu>0.2</mu>
                <mu2>0.2</mu2>
              </ode>
              <torsional>
                <ode/>
              </torsional>
            </friction>
            <bounce/>
          </surface>
          <max_contacts>10</max_contacts>
        </collision>
        <visual name='RR_thigh_visual'>
          <pose>0 0 0 0 -0 0</pose>
          <geometry>
            <mesh>
              <scale>1 1 1</scale>
              <uri>file:///home/apampattiwar3/ros2_ws/install/go2_description/share/go2_description/meshes/thigh_mirror.dae</uri>
            </mesh>
          </geometry>
        </visual>
        <visual name='RR_thigh_fixed_joint_lump__RR_calf_rotor_visual_1'>
          <pose>0 0.03235 0 1.5708 -0 0</pose>
          <geometry>
            <cylinder>
              <length>0.02</length>
              <radius>0.035</radius>
            </cylinder>
          </geometry>
        </visual>
        <self_collide>1</self_collide>
        <enable_wind>0</enable_wind>
        <kinematic>0</kinematic>
      </link>
      <joint name='RR_calf_joint' type='revolute'>
        <pose relative_to='RR_thigh'>0 0 -0.213 0 -0 0</pose>
        <parent>RR_thigh</parent>
        <child>RR_calf</child>
        <axis>
          <xyz>0 1 0</xyz>
          <limit>
            <lower>-2.7227</lower>
            <upper>-0.83776</upper>
            <effort>35.55</effort>
            <velocity>20.06</velocity>
          </limit>
          <dynamics>
            <damping>0</damping>
            <friction>0</friction>
            <spring_reference>0</spring_reference>
            <spring_stiffness>0</spring_stiffness>
          </dynamics>
        </axis>
      </joint>
      <link name='RR_calf'>
        <pose relative_to='RR_calf_joint'>0 0 0 0 -0 0</pose>
        <inertial>
          <pose>0.003944 -0.000702 -0.142477 0 -0 0</pose>
          <mass>0.214</mass>
          <inertia>
            <ixx>0.00150432</ixx>
            <ixy>5.70698e-07</ixy>
            <ixz>-5.98808e-06</ixz>
            <iyy>0.00152557</iyy>
            <iyz>1.24056e-05</iyz>
            <izz>4.38377e-05</izz>
          </inertia>
        </inertial>
        <collision name='RR_calf_collision'>
          <pose>0 0 -0.1065 0 -0 0</pose>
          <geometry>
            <cylinder>
              <length>0.213</length>
              <radius>0.008</radius>
            </cylinder>
          </geometry>
          <surface>
            <contact>
              <ode/>
            </contact>
            <friction>
              <ode>
                <mu>0.2</mu>
                <mu2>0.2</mu2>
              </ode>
              <torsional>
                <ode/>
              </torsional>
            </friction>
            <bounce/>
          </surface>
          <max_contacts>10</max_contacts>
        </collision>
        <collision name='RR_calf_fixed_joint_lump__RR_foot_collision_1'>
          <pose>0 0 -0.213 0 -0 0</pose>
          <geometry>
            <sphere>
              <radius>0.02</radius>
            </sphere>
          </geometry>
          <surface>
            <contact>
              <ode>
                <kp>1e+06</kp>
                <kd>1</kd>
              </ode>
            </contact>
            <friction>
              <ode>
                <mu>0.6</mu>
                <mu2>0.6</mu2>
              </ode>
              <torsional>
                <ode/>
              </torsional>
            </friction>
            <bounce/>
          </surface>
          <max_contacts>10</max_contacts>
        </collision>
        <visual name='RR_calf_visual'>
          <pose>0 0 0 0 -0 0</pose>
          <geometry>
            <mesh>
              <scale>1 1 1</scale>
              <uri>file:///home/apampattiwar3/ros2_ws/install/go2_description/share/go2_description/meshes/calf.dae</uri>
            </mesh>
          </geometry>
        </visual>
        <visual name='RR_calf_fixed_joint_lump__RR_foot_visual_1'>
          <pose>0 0 -0.213 0 -0 0</pose>
          <geometry>
            <sphere>
              <radius>0.01</radius>
            </sphere>
          </geometry>
        </visual>
        <self_collide>1</self_collide>
        <self_collide>1</self_collide>
        <enable_wind>0</enable_wind>
        <kinematic>0</kinematic>
      </link>
      <plugin name='gazebo_ros2_control' filename='libgazebo_ros2_control.so'>
        <parameters>/home/apampattiwar3/ros2_ws/install/go2_description/share/go2_description/config/ros_control/unitree_ros_control.yaml</parameters>
      </plugin>
      <plugin name='p3d_base_controller' filename='libgazebo_ros_p3d.so'>
        <ros>
          <remapping>odom:=ground_truth/state</remapping>
        </ros>
        <always_on>1</always_on>
        <body_name>base</body_name>
        <frame_name>odom</frame_name>
        <topic_name>odom</topic_name>
        <update_rate>500.0</update_rate>
        <xyz_offset>0 0 0</xyz_offset>
        <rpy_offset>0 0 0</rpy_offset>
        <gaussian_noise>0.01</gaussian_noise>
      </plugin>
      <static>0</static>
      <plugin name='camera' filename='librealsense_gazebo_plugin.so'>
        <prefix>camera</prefix>
        <depthUpdateRate>60.0</depthUpdateRate>
        <colorUpdateRate>60.0</colorUpdateRate>
        <infraredUpdateRate>60.0</infraredUpdateRate>
        <depthTopicName>camera/depth/image_raw</depthTopicName>
        <depthCameraInfoTopicName>camera/depth/camera_info</depthCameraInfoTopicName>
        <colorTopicName>camera/color/image_raw</colorTopicName>
        <colorCameraInfoTopicName>camera/color/camera_info</colorCameraInfoTopicName>
        <infrared1TopicName>camera/infra1/image_raw</infrared1TopicName>
        <infrared1CameraInfoTopicName>camera/infra1/camera_info</infrared1CameraInfoTopicName>
        <infrared2TopicName>camera/infra2/image_raw</infrared2TopicName>
        <infrared2CameraInfoTopicName>camera/infra2/camera_info</infrared2CameraInfoTopicName>
        <colorOpticalframeName>camera_color_optical_frame</colorOpticalframeName>
        <depthOpticalframeName>camera_depth_optical_frame</depthOpticalframeName>
        <infrared1OpticalframeName>camera_left_ir_optical_frame</infrared1OpticalframeName>
        <infrared2OpticalframeName>camera_right_ir_optical_frame</infrared2OpticalframeName>
        <rangeMinDepth>0.1</rangeMinDepth>
        <rangeMaxDepth>3.0</rangeMaxDepth>
        <pointCloud>1</pointCloud>
        <pointCloudTopicName>camera/depth/points</pointCloudTopicName>
        <pointCloudCutoff>0.5</pointCloudCutoff>
      </plugin>
      <pose>0 0 0.5 0 -0 0</pose>
    </model>
  </world>
</sdf>
