<?xml version="1.0" ?>
<robot name="spot">
  <link name="base">
    <visual>
      <origin xyz="0 0 0" rpy="0 0 0"/>
      <geometry>
        <mesh filename="package://ocs2_robotic_assets/resources/spot/meshes/visual/body.dae"/>
      </geometry>
      <material name="base"> <color rgba="1 0.8431 0 1"/></material>
    </visual>
    <collision>
      <geometry>
        <box size="0.7 0.3 0.2"/>
      </geometry>
    </collision>
  </link>
  <link name="base_inertia">
    <inertial>
      <origin rpy="0.0 0.0 0.0" xyz="0.006394396536052227 -9.812158532440662e-05 0.0009113792330026627"/>
      <mass value="16.0"/>
      <inertia ixx="0.017938806" ixy="0.00387963" ixz="0.001500772" iyy="0.370887745" iyz="6.8963e-05" izz="0.372497653"/>
    </inertial>
  </link>
  <joint name="base_inertia_joint" type="fixed">
    <origin xyz="0 0 0" rpy="0 0 0" />
    <parent link="base" />
    <child link="base_inertia" />
  </joint>
  <link name="fl_hip">
    <visual>
      <origin rpy="0 0 0" xyz="0 0 0"/>
      <geometry>
        <mesh filename="package://ocs2_robotic_assets/resources/spot/meshes/visual/fl_hip.dae"/>
      </geometry>
    </visual>
    <inertial>
      <origin rpy="-0.716521349312305 0.02956473059648479 0.03655230014702582" xyz="-0.005374345928430557 0.012841847725212574 9.875232353806496e-05"/>
      <mass value="2.0"/>
      <inertia ixx="0.0030083333333333333" ixy="0.0" ixz="0.0" iyy="0.004320833333333334" iyz="0.0" izz="0.004320833333333334"/>
    </inertial>
  </link>
  <joint name="LF_HAA" type="revolute">
    <origin rpy="0 0 0" xyz="0.29785 0.05500 0.00000"/>
    <axis xyz="1 0 0"/>
    <parent link="base"/>
    <child link="fl_hip"/>
    <limit effort="80" lower="-0.78539816339744827899" upper="0.78539816339744827899" velocity="7.5"/>
  </joint>
  <link name="fl_uleg">
  <collision>
      <origin rpy="0 0 0" xyz="-0.0 0 -0.15"/>
      <geometry>
        <cylinder length="0.3" radius="0.05"/>
      </geometry>
    </collision>
    <visual>
      <origin rpy="0 0 0" xyz="0 0 0"/>
      <geometry>
        <mesh filename="package://ocs2_robotic_assets/resources/spot/meshes/visual/fl_uleg.dae"/>
      </geometry>
      <material name="fl_uleg">
        <color rgba="1 0.8431 0 1"/>
      </material>
    </visual>
    <inertial>
      <origin rpy="-0.26437828203369795 -0.04853174570753804 0.024046963096353124" xyz="0.005142373498529196 -0.0024323679972440004 -0.12100915610790253"/>
      <mass value="1.0"/>
      <inertia ixx="0.01523333333333333" ixy="0.0" ixz="0.0" iyy="0.01523333333333333" iyz="0.0" izz="0.0010666666666666667"/>
    </inertial>
  </link>
  <joint name="LF_HFE" type="revolute">
    <origin rpy="0 0 0" xyz="0.0 0.11080 0.0"/>
    <axis xyz="0 1      0"/>
    <parent link="fl_hip"/>
    <child link="fl_uleg"/>
    <limit effort="80" lower="-0.89884456477707963539" upper="2.2951079663725435509" velocity="7.5"/>
  </joint>
  <link name="fl_lleg">
  <collision>
      <origin rpy="0 0 0" xyz="-0.0 0 -0.155"/>
      <geometry>
        <cylinder length="0.30" radius="0.03"/>
      </geometry>
    </collision>
    <visual>
      <origin rpy="0 0 0" xyz="0 0 0"/>
      <geometry>
        <mesh filename="package://ocs2_robotic_assets/resources/spot/meshes/visual/fl_lleg.dae"/>
      </geometry>
    </visual>
    <collision name="LF_FOOT_collision_sensor">
      <origin rpy="0 0 0" xyz="0 0 -0.335"/>
      <geometry>
        <sphere radius="0.035"/>
      </geometry>
    </collision>
    <inertial>
      <origin rpy="-0.007266925694167092 -0.009591807116834161 0.00035255970529224356" xyz="0.00225794012658298 4.607596201822162e-05 -0.1800822913646698"/>
      <mass value="0.5"/>
      <inertia ixx="0.007416666666666665" ixy="0.0" ixz="0.0" iyy="0.007416666666666665" iyz="0.0" izz="0.00013333333333333334"/>
    </inertial>
  </link>
  <joint name="LF_KFE" type="revolute">
    <origin rpy="0 0 0" xyz="0.025 0.000 -0.3200"/>
    <axis xyz="0 1 0"/>
    <parent link="fl_uleg"/>
    <child link="fl_lleg"/>
    <limit effort="80" lower="-2.7929" upper="-0.254402" velocity="7.5"/>
  </joint>
  <link name="LF_FOOT"/>
  <joint name="LF_FOOT_JOINT" type="fixed">
    <origin rpy="0 0 0" xyz="-0.02 0.0 -0.370"/>
    <parent link="fl_lleg"/>
    <child link="LF_FOOT"/>
  </joint>
  <link name="fr_hip">
    <visual>
      <origin rpy="0 0 0" xyz="0 0 0"/>
      <geometry>
        <mesh filename="package://ocs2_robotic_assets/resources/spot/meshes/visual/fr_hip.dae"/>
      </geometry>
      <material name="fr_hip">
        <color rgba="0.2 0.2 0.2 1"/>
      </material>
    </visual>
    <inertial>
      <origin rpy="0.7165213493123055 -0.02956473059648479 0.03655230014702582" xyz="-0.005374345928430557 -0.012841847725212574 -9.875232353806496e-05"/>
      <mass value="2.0"/>
      <inertia ixx="0.0030083333333333333" ixy="0.0" ixz="0.0" iyy="0.004320833333333334" iyz="0.0" izz="0.004320833333333334"/>
    </inertial>
  </link>
  <joint name="RF_HAA" type="revolute">
    <origin rpy="0 0 0" xyz="0.29785 -0.05500 0.00000"/>
    <axis xyz="1 0 0"/>
    <parent link="base"/>
    <child link="fr_hip"/>
    <limit effort="80" lower="-0.78539816339744827899" upper="0.78539816339744827899" velocity="7.5"/>
  </joint>
  <link name="fr_uleg">
  <collision>
      <origin rpy="0 0 0" xyz="-0.0 0 -0.15"/>
      <geometry>
        <cylinder length="0.3" radius="0.05"/>
      </geometry>
    </collision>
    <visual>
      <origin rpy="0 0 0" xyz="0 0 0"/>
      <geometry>
        <mesh filename="package://ocs2_robotic_assets/resources/spot/meshes/visual/fr_uleg.dae"/>
      </geometry>
      <material name="fr_uleg">
        <color rgba="1 0.8431 0 1"/>
      </material>
    </visual>
    <inertial>
      <origin rpy="0.2643905306958363 -0.04853174688302708 -0.024046943559834943" xyz="0.005142373498529196 0.0024323677644133568 -0.12100915610790253"/>
      <mass value="1.0"/>
      <inertia ixx="0.01523333333333333" ixy="0.0" ixz="0.0" iyy="0.01523333333333333" iyz="0.0" izz="0.0010666666666666667"/>
    </inertial>
  </link>
  <joint name="RF_HFE" type="revolute">
    <origin rpy="0 0 0" xyz="0.0 -0.11080 0.0"/>
    <axis xyz="0  1      0"/>
    <parent link="fr_hip"/>
    <child link="fr_uleg"/>
    <limit effort="80" lower="-0.89884456477707963539" upper="2.2951079663725435509" velocity="7.5"/>
  </joint>
  <link name="fr_lleg">
  <collision>
      <origin rpy="0 0 0" xyz="-0.0 0 -0.155"/>
      <geometry>
        <cylinder length="0.30" radius="0.03"/>
      </geometry>
    </collision>
    <visual>
      <origin rpy="0 0 0" xyz="0 0 0"/>
      <geometry>
        <mesh filename="package://ocs2_robotic_assets/resources/spot/meshes/visual/fr_lleg.dae"/>
      </geometry>
    </visual>
    <collision name="RF_FOOT_collision_sensor">
      <origin rpy="0 0 0" xyz="0 0 -0.335"/>
      <geometry>
        <sphere radius="0.035"/>
      </geometry>
    </collision>
    <inertial>
      <origin rpy="-0.007266925694167092 -0.009591807116834161 0.00035255970529224356" xyz="0.00225794012658298 4.607596201822162e-05 -0.1800822913646698"/>
      <mass value="0.5"/>
      <inertia ixx="0.007416666666666665" ixy="0.0" ixz="0.0" iyy="0.007416666666666665" iyz="0.0" izz="0.00013333333333333334"/>
    </inertial>
  </link>
  <joint name="RF_KFE" type="revolute">
    <origin rpy="0 0 0" xyz="0.025 0.000 -0.3200"/>
    <axis xyz="0 1 0"/>
    <parent link="fr_uleg"/>
    <child link="fr_lleg"/>
    <limit effort="80" lower="-2.7929" upper="-0.254402" velocity="7.5"/>
  </joint>
  <link name="RF_FOOT"/>
  <joint name="RF_FOOT_JOINT" type="fixed">
    <origin rpy="0 0 0" xyz="-0.02 0.0 -0.370"/>
    <parent link="fr_lleg"/>
    <child link="RF_FOOT"/>
  </joint>
  <link name="hl_hip">
    <visual>
      <origin rpy="0 0 0" xyz="0 0 0"/>
      <geometry>
        <mesh filename="package://ocs2_robotic_assets/resources/spot/meshes/visual/hl_hip.dae"/>
      </geometry>
      <material name="hl_hip">
        <color rgba="0.2 0.2 0.2 1"/>
      </material>
    </visual>
    <inertial>
      <origin rpy="0.7165213493123055 0.02956473059648479 -0.03655230014702582" xyz="0.005374345928430557 0.012841847725212574 -9.875232353806496e-05"/>
      <mass value="2.0"/>
      <inertia ixx="0.0030083333333333333" ixy="0.0" ixz="0.0" iyy="0.004320833333333334" iyz="0.0" izz="0.004320833333333334"/>
    </inertial>
  </link>
  <joint name="LH_HAA" type="revolute">
    <origin rpy="0 0 0" xyz="-0.29785 0.05500 0.00000"/>
    <axis xyz="1 0 0"/>
    <parent link="base"/>
    <child link="hl_hip"/>
    <limit effort="80" lower="-0.78539816339744827899" upper="0.78539816339744827899" velocity="7.5"/>
  </joint>
  <link name="hl_uleg">
  <collision>
      <origin rpy="0 0 0" xyz="-0.0 0 -0.15"/>
      <geometry>
        <cylinder length="0.3" radius="0.05"/>
      </geometry>
    </collision>
    <visual>
      <origin rpy="0 0 0" xyz="0 0 0"/>
      <geometry>
        <mesh filename="package://ocs2_robotic_assets/resources/spot/meshes/visual/hl_uleg.dae"/>
      </geometry>
      <material name="hl_uleg">
        <color rgba="1 0.8431 0 1"/>
      </material>
    </visual>
    <inertial>
      <origin rpy="-0.26437828203369795 -0.04853174570753804 0.024046963096353124" xyz="0.005142373498529196 -0.0024323679972440004 -0.12100915610790253"/>
      <mass value="1.0"/>
      <inertia ixx="0.01523333333333333" ixy="0.0" ixz="0.0" iyy="0.01523333333333333" iyz="0.0" izz="0.0010666666666666667"/>
    </inertial>
  </link>
  <joint name="LH_HFE" type="revolute">
    <origin rpy="0 0 0" xyz="0.0 0.11080 0.0"/>
    <axis xyz="0 1      0"/>
    <parent link="hl_hip"/>
    <child link="hl_uleg"/>
    <limit effort="80" lower="-0.89884456477707963539" upper="2.2951079663725435509" velocity="7.5"/>
  </joint>
  <link name="hl_lleg">
  <collision>
      <origin rpy="0 0 0" xyz="-0.0 0 -0.155"/>
      <geometry>
        <cylinder length="0.30" radius="0.03"/>
      </geometry>
    </collision>
    <visual>
      <origin rpy="0 0 0" xyz="0 0 0"/>
      <geometry>
        <mesh filename="package://ocs2_robotic_assets/resources/spot/meshes/visual/hl_lleg.dae"/>
      </geometry>
    </visual>
    <collision name="LH_FOOT_collision_sensor">
      <origin rpy="0 0 0" xyz="0 0 -0.335"/>
      <geometry>
        <sphere radius="0.035"/>
      </geometry>
    </collision>
    <inertial>
      <origin rpy="-0.007266925694167092 -0.009591807116834161 0.00035255970529224356" xyz="0.00225794012658298 4.607596201822162e-05 -0.1800822913646698"/>
      <mass value="0.5"/>
      <inertia ixx="0.007416666666666665" ixy="0.0" ixz="0.0" iyy="0.007416666666666665" iyz="0.0" izz="0.00013333333333333334"/>
    </inertial>
  </link>
  <joint name="LH_KFE" type="revolute">
    <origin rpy="0 0 0" xyz="0.025 0.000 -0.3200"/>
    <axis xyz="0 1 0"/>
    <parent link="hl_uleg"/>
    <child link="hl_lleg"/>
    <limit effort="80" lower="-2.7929" upper="-0.254402" velocity="7.5"/>
  </joint>
  <link name="LH_FOOT"/>
  <joint name="LH_FOOT_JOINT" type="fixed">
    <origin rpy="0 0 0" xyz="-0.02 0.0 -0.370"/>
    <parent link="hl_lleg"/>
    <child link="LH_FOOT"/>
  </joint>
  <link name="hr_hip">
    <visual>
      <origin rpy="0 0 0" xyz="0 0 0"/>
      <geometry>
        <mesh filename="package://ocs2_robotic_assets/resources/spot/meshes/visual/hr_hip.dae"/>
      </geometry>
      <material name="hr_hip">
        <color rgba="0.2 0.2 0.2 1"/>
      </material>
    </visual>
    <inertial>
      <origin rpy="-0.716521349312305 -0.02956473059648479 -0.03655230014702582" xyz="0.005374345928430557 -0.012841847725212574 9.875232353806496e-05"/>
      <mass value="2.0"/>
      <inertia ixx="0.0030083333333333333" ixy="0.0" ixz="0.0" iyy="0.004320833333333334" iyz="0.0" izz="0.004320833333333334"/>
    </inertial>
  </link>
  <joint name="RH_HAA" type="revolute">
    <origin rpy="0 0 0" xyz="-0.29785 -0.05500 0.00000"/>
    <axis xyz="1 0 0"/>
    <parent link="base"/>
    <child link="hr_hip"/>
    <limit effort="80" lower="-0.78539816339744827899" upper="0.78539816339744827899" velocity="7.5"/>
  </joint>
  <link name="hr_uleg">
  <collision>
      <origin rpy="0 0 0" xyz="-0.0 0 -0.15"/>
      <geometry>
        <cylinder length="0.3" radius="0.05"/>
      </geometry>
    </collision>
    <visual>
      <origin rpy="0 0 0" xyz="0 0 0"/>
      <geometry>
        <mesh filename="package://ocs2_robotic_assets/resources/spot/meshes/visual/hr_uleg.dae"/>
      </geometry>
      <material name="hr_uleg">
        <color rgba="1 0.8431 0 1"/>
      </material>
    </visual>
    <inertial>
      <origin rpy="0.2643905306958363 -0.04853174688302708 -0.024046943559834943" xyz="0.005142373498529196 0.0024323677644133568 -0.12100915610790253"/>
      <mass value="1.0"/>
      <inertia ixx="0.01523333333333333" ixy="0.0" ixz="0.0" iyy="0.01523333333333333" iyz="0.0" izz="0.0010666666666666667"/>
    </inertial>
  </link>
  <joint name="RH_HFE" type="revolute">
    <origin rpy="0 0 0" xyz="0.0 -0.11080 0.0"/>
    <axis xyz="0  1      0"/>
    <parent link="hr_hip"/>
    <child link="hr_uleg"/>
    <limit effort="80" lower="-0.89884456477707963539" upper="2.2951079663725435509" velocity="7.5"/>
  </joint>
  <link name="hr_lleg">
  <collision>
      <origin rpy="0 0 0" xyz="-0.0 0 -0.155"/>
      <geometry>
        <cylinder length="0.30" radius="0.03"/>
      </geometry>
    </collision>
    <visual>
      <origin rpy="0 0 0" xyz="0 0 0"/>
      <geometry>
        <mesh filename="package://ocs2_robotic_assets/resources/spot/meshes/visual/hr_lleg.dae"/>
      </geometry>
    </visual>
    <collision name="RH_FOOT_collision_sensor">
      <origin rpy="0 0 0" xyz="0 0 -0.335"/>
      <geometry>
        <sphere radius="0.035"/>
      </geometry>
    </collision>
    <inertial>
      <origin rpy="-0.007266925694167092 -0.009591807116834161 0.00035255970529224356" xyz="0.00225794012658298 4.607596201822162e-05 -0.1800822913646698"/>
      <mass value="0.5"/>
      <inertia ixx="0.007416666666666665" ixy="0.0" ixz="0.0" iyy="0.007416666666666665" iyz="0.0" izz="0.00013333333333333334"/>
    </inertial>
  </link>
  <joint name="RH_KFE" type="revolute">
    <origin rpy="0 0 0" xyz="0.025 0.000 -0.3200"/>
    <axis xyz="0 1 0"/>
    <parent link="hr_uleg"/>
    <child link="hr_lleg"/>
    <limit effort="80" lower="-2.7929" upper="-0.254402" velocity="7.5"/>
  </joint>
  <link name="RH_FOOT"/>
  <joint name="RH_FOOT_JOINT" type="fixed">
    <origin rpy="0 0 0" xyz="-0.02 0.0 -0.370"/>
    <parent link="hr_lleg"/>
    <child link="RH_FOOT"/>
  </joint>

  <!-- Camera - NOTE: not real placement of camera frame! -->
  <joint name="camera_joint" type="fixed">
      <parent link="base"/>
      <child link="camera_link"/>
      <origin rpy="0 0 0" xyz="0.42 0 0"/>
  </joint>
  <link name="camera_link">
  <inertial>
      <mass value="1e-5"/>
      <inertia ixx="1e-3" ixy="0.0" ixz="0.0" iyy="1e-3" iyz="0.0" izz="1e-3"/>
    </inertial>
    </link>
  <joint name="camera_optical_joint" type="fixed">
    <origin xyz="0 0 0" rpy="-1.57 0 -1.57"/>
    <parent link="camera_link"/>
    <child link="camera_optical"/>
  </joint>
  <link name="camera_optical">
  <inertial>
      <mass value="1e-5"/>
      <inertia ixx="1e-3" ixy="0.0" ixz="0.0" iyy="1e-3" iyz="0.0" izz="1e-3"/>
    </inertial>
  </link>

  <!-- Camera - front right -->

  <joint name="camera_joint_front_right" type="fixed">
      <parent link="base"/>
      <child link="camera_link_front_right"/>
      <origin xyz="0.415 -0.037 -0.01" rpy="-1.355558 0.353917 0.554196"/>
  </joint>
  <link name="camera_link_front_right">
  <inertial>
    <mass value="1e-5"/>
      <inertia ixx="1e-3" ixy="0.0" ixz="0.0" iyy="1e-3" iyz="0.0" izz="1e-3"/>
    </inertial>
    </link>
  <joint name="camera_optical_joint_front_right" type="fixed">
    <origin xyz="0 0 0" rpy="-1.57 0 -1.57"/>
    <parent link="camera_link_front_right"/>
    <child link="camera_optical_front_right"/>
  </joint>
  <link name="camera_optical_front_right">
  <inertial>
      <mass value="1e-5"/>
      <inertia ixx="1e-3" ixy="0.0" ixz="0.0" iyy="1e-3" iyz="0.0" izz="1e-3"/>
    </inertial>
  </link>

  <!-- Camera - front left -->

  <joint name="camera_joint_front_left" type="fixed">
      <parent link="base"/>
      <child link="camera_link_front_left"/>
      <origin xyz="0.415 0.037 -0.01" rpy="1.355558 0.353917 -0.554196"/>
  </joint>
  <link name="camera_link_front_left">
  <inertial>
    <mass value="1e-5"/>
      <inertia ixx="1e-3" ixy="0.0" ixz="0.0" iyy="1e-3" iyz="0.0" izz="1e-3"/>
    </inertial>
    </link>
  <joint name="camera_optical_joint_front_left" type="fixed">
    <origin xyz="0 0 0" rpy="-1.57 0 -1.57"/>
    <parent link="camera_link_front_left"/>
    <child link="camera_optical_front_left"/>
  </joint>
  <link name="camera_optical_front_left">
  <inertial>
      <mass value="1e-5"/>
      <inertia ixx="1e-3" ixy="0.0" ixz="0.0" iyy="1e-3" iyz="0.0" izz="1e-3"/>
    </inertial>
  </link>


  <!-- Camera - right -->

  <joint name="camera_joint_right" type="fixed">
      <parent link="base"/>
      <child link="camera_link_right"/>
      <origin xyz="-0.125 -0.12 0.035" rpy="3.141592653589793 0.2 -1.5707963267948966"/>
  </joint>
  <link name="camera_link_right">
  <inertial>
    <mass value="1e-5"/>
      <inertia ixx="1e-3" ixy="0.0" ixz="0.0" iyy="1e-3" iyz="0.0" izz="1e-3"/>
    </inertial>
    </link>
  <joint name="camera_optical_joint_right" type="fixed">
    <origin xyz="0 0 0" rpy="-1.57 0 -1.57"/>
    <parent link="camera_link_right"/>
    <child link="camera_optical_right"/>
  </joint>
  <link name="camera_optical_right">
  <inertial>
      <mass value="1e-5"/>
      <inertia ixx="1e-3" ixy="0.0" ixz="0.0" iyy="1e-3" iyz="0.0" izz="1e-3"/>
    </inertial>
  </link>

  <!-- Camera - left -->

  <joint name="camera_joint_left" type="fixed">
      <parent link="base"/>
      <child link="camera_link_left"/>
      <origin xyz="-0.125 0.12 0.035" rpy="3.141592653589793 0.2 1.5707963267948966"/>
  </joint>
  <link name="camera_link_left">
  <inertial>
    <mass value="1e-5"/>
      <inertia ixx="1e-3" ixy="0.0" ixz="0.0" iyy="1e-3" iyz="0.0" izz="1e-3"/>
    </inertial>
    </link>
  <joint name="camera_optical_joint_left" type="fixed">
    <origin xyz="0 0 0" rpy="-1.57 0 -1.57"/>
    <parent link="camera_link_left"/>
    <child link="camera_optical_left"/>
  </joint>
  <link name="camera_optical_left">
  <inertial>
      <mass value="1e-5"/>
      <inertia ixx="1e-3" ixy="0.0" ixz="0.0" iyy="1e-3" iyz="0.0" izz="1e-3"/>
    </inertial>
  </link>

  <!-- Camera - back -->

  <joint name="camera_joint_back" type="fixed">
      <parent link="base"/>
      <child link="camera_link_back"/>
      <origin xyz="-0.425 0 0.01" rpy="0 0.3 -3.141592653589793"/>
  </joint>
  <link name="camera_link_back">
  <inertial>
    <mass value="1e-5"/>
      <inertia ixx="1e-3" ixy="0.0" ixz="0.0" iyy="1e-3" iyz="0.0" izz="1e-3"/>
    </inertial>
    </link>
  <joint name="camera_optical_joint_back" type="fixed">
    <origin xyz="0 0 0" rpy="-1.57 0 -1.57"/>
    <parent link="camera_link_back"/>
    <child link="camera_optical_back"/>
  </joint>
  <link name="camera_optical_back">
  <inertial>
      <mass value="1e-5"/>
      <inertia ixx="1e-3" ixy="0.0" ixz="0.0" iyy="1e-3" iyz="0.0" izz="1e-3"/>
    </inertial>
  </link>



</robot>
